{
 "cells": [
  {
   "cell_type": "code",
   "execution_count": 15,
   "id": "2d929f93",
   "metadata": {},
   "outputs": [
    {
     "name": "stdout",
     "output_type": "stream",
     "text": [
      "ERROR! Session/line number was not unique in database. History logging moved to new session 85\n"
     ]
    }
   ],
   "source": [
    "import numpy as np\n",
    "import matplotlib.pyplot as plot\n",
    "import tensorflow as tf"
   ]
  },
  {
   "cell_type": "code",
   "execution_count": null,
   "id": "638ce50c",
   "metadata": {},
   "outputs": [
    {
     "name": "stderr",
     "output_type": "stream",
     "text": [
      "ERROR:root:Internal Python error in the inspect module.\n",
      "Below is the traceback from this internal error.\n",
      "\n",
      "ERROR:root:Internal Python error in the inspect module.\n",
      "Below is the traceback from this internal error.\n",
      "\n",
      "ERROR:root:Internal Python error in the inspect module.\n",
      "Below is the traceback from this internal error.\n",
      "\n"
     ]
    },
    {
     "name": "stdout",
     "output_type": "stream",
     "text": [
      "ERROR! Session/line number was not unique in database. History logging moved to new session 87\n",
      "Traceback (most recent call last):\n",
      "  File \"/Users/hiradekeishi/opt/anaconda3/envs/py3-TF2.0/lib/python3.7/site-packages/IPython/core/interactiveshell.py\", line 3457, in run_code\n",
      "    exec(code_obj, self.user_global_ns, self.user_ns)\n",
      "  File \"/var/folders/7_/5ly65s3j46zcgtgg9r0sjm940000gn/T/ipykernel_87487/4225855434.py\", line 4, in <module>\n",
      "    train_inputs = npz['inputs'].astype(np.feat)\n",
      "  File \"/Users/hiradekeishi/opt/anaconda3/envs/py3-TF2.0/lib/python3.7/site-packages/numpy/__init__.py\", line 314, in __getattr__\n",
      "    \"{!r}\".format(__name__, attr))\n",
      "AttributeError: module 'numpy' has no attribute 'feat'\n",
      "\n",
      "During handling of the above exception, another exception occurred:\n",
      "\n",
      "Traceback (most recent call last):\n",
      "  File \"/Users/hiradekeishi/opt/anaconda3/envs/py3-TF2.0/lib/python3.7/site-packages/IPython/core/interactiveshell.py\", line 2077, in showtraceback\n",
      "    stb = value._render_traceback_()\n",
      "AttributeError: 'AttributeError' object has no attribute '_render_traceback_'\n",
      "\n",
      "During handling of the above exception, another exception occurred:\n",
      "\n",
      "Traceback (most recent call last):\n",
      "  File \"/Users/hiradekeishi/opt/anaconda3/envs/py3-TF2.0/lib/python3.7/site-packages/IPython/core/ultratb.py\", line 1101, in get_records\n",
      "    return _fixed_getinnerframes(etb, number_of_lines_of_context, tb_offset)\n",
      "  File \"/Users/hiradekeishi/opt/anaconda3/envs/py3-TF2.0/lib/python3.7/site-packages/IPython/core/ultratb.py\", line 248, in wrapped\n",
      "    return f(*args, **kwargs)\n",
      "  File \"/Users/hiradekeishi/opt/anaconda3/envs/py3-TF2.0/lib/python3.7/site-packages/IPython/core/ultratb.py\", line 281, in _fixed_getinnerframes\n",
      "    records = fix_frame_records_filenames(inspect.getinnerframes(etb, context))\n",
      "  File \"/Users/hiradekeishi/opt/anaconda3/envs/py3-TF2.0/lib/python3.7/inspect.py\", line 1502, in getinnerframes\n",
      "    frameinfo = (tb.tb_frame,) + getframeinfo(tb, context)\n",
      "  File \"/Users/hiradekeishi/opt/anaconda3/envs/py3-TF2.0/lib/python3.7/inspect.py\", line 1460, in getframeinfo\n",
      "    filename = getsourcefile(frame) or getfile(frame)\n",
      "  File \"/Users/hiradekeishi/opt/anaconda3/envs/py3-TF2.0/lib/python3.7/inspect.py\", line 696, in getsourcefile\n",
      "    if getattr(getmodule(object, filename), '__loader__', None) is not None:\n",
      "  File \"/Users/hiradekeishi/opt/anaconda3/envs/py3-TF2.0/lib/python3.7/inspect.py\", line 733, in getmodule\n",
      "    if ismodule(module) and hasattr(module, '__file__'):\n",
      "  File \"/Users/hiradekeishi/opt/anaconda3/envs/py3-TF2.0/lib/python3.7/site-packages/tensorflow/__init__.py\", line 50, in __getattr__\n",
      "    from ._api.v2 import bitwise\n",
      "  File \"/Users/hiradekeishi/opt/anaconda3/envs/py3-TF2.0/lib/python3.7/site-packages/tensorflow/__init__.py\", line 44, in _load\n",
      "  File \"/Users/hiradekeishi/opt/anaconda3/envs/py3-TF2.0/lib/python3.7/importlib/__init__.py\", line 127, in import_module\n",
      "    return _bootstrap._gcd_import(name[level:], package, level)\n",
      "  File \"<frozen importlib._bootstrap>\", line 1006, in _gcd_import\n",
      "  File \"<frozen importlib._bootstrap>\", line 983, in _find_and_load\n",
      "  File \"<frozen importlib._bootstrap>\", line 965, in _find_and_load_unlocked\n",
      "ModuleNotFoundError: No module named 'tensorflow_core.estimator'\n",
      "Traceback (most recent call last):\n",
      "  File \"/Users/hiradekeishi/opt/anaconda3/envs/py3-TF2.0/lib/python3.7/site-packages/IPython/core/interactiveshell.py\", line 3457, in run_code\n",
      "    exec(code_obj, self.user_global_ns, self.user_ns)\n",
      "  File \"/var/folders/7_/5ly65s3j46zcgtgg9r0sjm940000gn/T/ipykernel_87487/4225855434.py\", line 4, in <module>\n",
      "    train_inputs = npz['inputs'].astype(np.feat)\n",
      "  File \"/Users/hiradekeishi/opt/anaconda3/envs/py3-TF2.0/lib/python3.7/site-packages/numpy/__init__.py\", line 314, in __getattr__\n",
      "    \"{!r}\".format(__name__, attr))\n",
      "AttributeError: module 'numpy' has no attribute 'feat'\n",
      "\n",
      "During handling of the above exception, another exception occurred:\n",
      "\n",
      "Traceback (most recent call last):\n",
      "  File \"/Users/hiradekeishi/opt/anaconda3/envs/py3-TF2.0/lib/python3.7/site-packages/IPython/core/interactiveshell.py\", line 2077, in showtraceback\n",
      "    stb = value._render_traceback_()\n",
      "AttributeError: 'AttributeError' object has no attribute '_render_traceback_'\n",
      "\n",
      "During handling of the above exception, another exception occurred:\n",
      "\n",
      "Traceback (most recent call last):\n",
      "  File \"/Users/hiradekeishi/opt/anaconda3/envs/py3-TF2.0/lib/python3.7/site-packages/IPython/core/interactiveshell.py\", line 3377, in run_ast_nodes\n",
      "    if (await self.run_code(code, result,  async_=asy)):\n",
      "  File \"/Users/hiradekeishi/opt/anaconda3/envs/py3-TF2.0/lib/python3.7/site-packages/IPython/core/interactiveshell.py\", line 3474, in run_code\n",
      "    self.showtraceback(running_compiled_code=True)\n",
      "  File \"/Users/hiradekeishi/opt/anaconda3/envs/py3-TF2.0/lib/python3.7/site-packages/IPython/core/interactiveshell.py\", line 2080, in showtraceback\n",
      "    value, tb, tb_offset=tb_offset)\n",
      "  File \"/Users/hiradekeishi/opt/anaconda3/envs/py3-TF2.0/lib/python3.7/site-packages/IPython/core/ultratb.py\", line 1368, in structured_traceback\n",
      "    self, etype, value, tb, tb_offset, number_of_lines_of_context)\n",
      "  File \"/Users/hiradekeishi/opt/anaconda3/envs/py3-TF2.0/lib/python3.7/site-packages/IPython/core/ultratb.py\", line 1268, in structured_traceback\n",
      "    self, etype, value, tb, tb_offset, number_of_lines_of_context\n",
      "  File \"/Users/hiradekeishi/opt/anaconda3/envs/py3-TF2.0/lib/python3.7/site-packages/IPython/core/ultratb.py\", line 1125, in structured_traceback\n",
      "    tb_offset)\n",
      "  File \"/Users/hiradekeishi/opt/anaconda3/envs/py3-TF2.0/lib/python3.7/site-packages/IPython/core/ultratb.py\", line 1082, in format_exception_as_a_whole\n",
      "    last_unique, recursion_repeat = find_recursion(orig_etype, evalue, records)\n",
      "  File \"/Users/hiradekeishi/opt/anaconda3/envs/py3-TF2.0/lib/python3.7/site-packages/IPython/core/ultratb.py\", line 382, in find_recursion\n",
      "    return len(records), 0\n",
      "TypeError: object of type 'NoneType' has no len()\n",
      "\n",
      "During handling of the above exception, another exception occurred:\n",
      "\n",
      "Traceback (most recent call last):\n",
      "  File \"/Users/hiradekeishi/opt/anaconda3/envs/py3-TF2.0/lib/python3.7/site-packages/IPython/core/interactiveshell.py\", line 2077, in showtraceback\n",
      "    stb = value._render_traceback_()\n",
      "AttributeError: 'TypeError' object has no attribute '_render_traceback_'\n",
      "\n",
      "During handling of the above exception, another exception occurred:\n",
      "\n",
      "Traceback (most recent call last):\n",
      "  File \"/Users/hiradekeishi/opt/anaconda3/envs/py3-TF2.0/lib/python3.7/site-packages/IPython/core/ultratb.py\", line 1101, in get_records\n",
      "    return _fixed_getinnerframes(etb, number_of_lines_of_context, tb_offset)\n",
      "  File \"/Users/hiradekeishi/opt/anaconda3/envs/py3-TF2.0/lib/python3.7/site-packages/IPython/core/ultratb.py\", line 248, in wrapped\n",
      "    return f(*args, **kwargs)\n",
      "  File \"/Users/hiradekeishi/opt/anaconda3/envs/py3-TF2.0/lib/python3.7/site-packages/IPython/core/ultratb.py\", line 281, in _fixed_getinnerframes\n",
      "    records = fix_frame_records_filenames(inspect.getinnerframes(etb, context))\n",
      "  File \"/Users/hiradekeishi/opt/anaconda3/envs/py3-TF2.0/lib/python3.7/inspect.py\", line 1502, in getinnerframes\n",
      "    frameinfo = (tb.tb_frame,) + getframeinfo(tb, context)\n",
      "  File \"/Users/hiradekeishi/opt/anaconda3/envs/py3-TF2.0/lib/python3.7/inspect.py\", line 1460, in getframeinfo\n",
      "    filename = getsourcefile(frame) or getfile(frame)\n",
      "  File \"/Users/hiradekeishi/opt/anaconda3/envs/py3-TF2.0/lib/python3.7/inspect.py\", line 696, in getsourcefile\n",
      "    if getattr(getmodule(object, filename), '__loader__', None) is not None:\n",
      "  File \"/Users/hiradekeishi/opt/anaconda3/envs/py3-TF2.0/lib/python3.7/inspect.py\", line 733, in getmodule\n",
      "    if ismodule(module) and hasattr(module, '__file__'):\n",
      "  File \"/Users/hiradekeishi/opt/anaconda3/envs/py3-TF2.0/lib/python3.7/site-packages/tensorflow/__init__.py\", line 50, in __getattr__\n",
      "    from ._api.v2 import bitwise\n",
      "  File \"/Users/hiradekeishi/opt/anaconda3/envs/py3-TF2.0/lib/python3.7/site-packages/tensorflow/__init__.py\", line 44, in _load\n",
      "  File \"/Users/hiradekeishi/opt/anaconda3/envs/py3-TF2.0/lib/python3.7/importlib/__init__.py\", line 127, in import_module\n",
      "    return _bootstrap._gcd_import(name[level:], package, level)\n",
      "  File \"<frozen importlib._bootstrap>\", line 1006, in _gcd_import\n",
      "  File \"<frozen importlib._bootstrap>\", line 983, in _find_and_load\n",
      "  File \"<frozen importlib._bootstrap>\", line 965, in _find_and_load_unlocked\n",
      "ModuleNotFoundError: No module named 'tensorflow_core.estimator'\n",
      "Traceback (most recent call last):\n",
      "  File \"/Users/hiradekeishi/opt/anaconda3/envs/py3-TF2.0/lib/python3.7/site-packages/IPython/core/interactiveshell.py\", line 3457, in run_code\n",
      "    exec(code_obj, self.user_global_ns, self.user_ns)\n",
      "  File \"/var/folders/7_/5ly65s3j46zcgtgg9r0sjm940000gn/T/ipykernel_87487/4225855434.py\", line 4, in <module>\n",
      "    train_inputs = npz['inputs'].astype(np.feat)\n",
      "  File \"/Users/hiradekeishi/opt/anaconda3/envs/py3-TF2.0/lib/python3.7/site-packages/numpy/__init__.py\", line 314, in __getattr__\n",
      "    \"{!r}\".format(__name__, attr))\n",
      "AttributeError: module 'numpy' has no attribute 'feat'\n",
      "\n",
      "During handling of the above exception, another exception occurred:\n",
      "\n",
      "Traceback (most recent call last):\n",
      "  File \"/Users/hiradekeishi/opt/anaconda3/envs/py3-TF2.0/lib/python3.7/site-packages/IPython/core/interactiveshell.py\", line 2077, in showtraceback\n",
      "    stb = value._render_traceback_()\n",
      "AttributeError: 'AttributeError' object has no attribute '_render_traceback_'\n",
      "\n",
      "During handling of the above exception, another exception occurred:\n",
      "\n",
      "Traceback (most recent call last):\n",
      "  File \"/Users/hiradekeishi/opt/anaconda3/envs/py3-TF2.0/lib/python3.7/site-packages/IPython/core/interactiveshell.py\", line 3377, in run_ast_nodes\n",
      "    if (await self.run_code(code, result,  async_=asy)):\n",
      "  File \"/Users/hiradekeishi/opt/anaconda3/envs/py3-TF2.0/lib/python3.7/site-packages/IPython/core/interactiveshell.py\", line 3474, in run_code\n",
      "    self.showtraceback(running_compiled_code=True)\n",
      "  File \"/Users/hiradekeishi/opt/anaconda3/envs/py3-TF2.0/lib/python3.7/site-packages/IPython/core/interactiveshell.py\", line 2080, in showtraceback\n",
      "    value, tb, tb_offset=tb_offset)\n",
      "  File \"/Users/hiradekeishi/opt/anaconda3/envs/py3-TF2.0/lib/python3.7/site-packages/IPython/core/ultratb.py\", line 1368, in structured_traceback\n",
      "    self, etype, value, tb, tb_offset, number_of_lines_of_context)\n",
      "  File \"/Users/hiradekeishi/opt/anaconda3/envs/py3-TF2.0/lib/python3.7/site-packages/IPython/core/ultratb.py\", line 1268, in structured_traceback\n",
      "    self, etype, value, tb, tb_offset, number_of_lines_of_context\n",
      "  File \"/Users/hiradekeishi/opt/anaconda3/envs/py3-TF2.0/lib/python3.7/site-packages/IPython/core/ultratb.py\", line 1125, in structured_traceback\n",
      "    tb_offset)\n",
      "  File \"/Users/hiradekeishi/opt/anaconda3/envs/py3-TF2.0/lib/python3.7/site-packages/IPython/core/ultratb.py\", line 1082, in format_exception_as_a_whole\n",
      "    last_unique, recursion_repeat = find_recursion(orig_etype, evalue, records)\n",
      "  File \"/Users/hiradekeishi/opt/anaconda3/envs/py3-TF2.0/lib/python3.7/site-packages/IPython/core/ultratb.py\", line 382, in find_recursion\n",
      "    return len(records), 0\n",
      "TypeError: object of type 'NoneType' has no len()\n",
      "\n",
      "During handling of the above exception, another exception occurred:\n",
      "\n",
      "Traceback (most recent call last):\n",
      "  File \"/Users/hiradekeishi/opt/anaconda3/envs/py3-TF2.0/lib/python3.7/site-packages/IPython/core/interactiveshell.py\", line 2077, in showtraceback\n",
      "    stb = value._render_traceback_()\n",
      "AttributeError: 'TypeError' object has no attribute '_render_traceback_'\n",
      "\n",
      "During handling of the above exception, another exception occurred:\n",
      "\n",
      "Traceback (most recent call last):\n",
      "  File \"/Users/hiradekeishi/opt/anaconda3/envs/py3-TF2.0/lib/python3.7/site-packages/IPython/core/interactiveshell.py\", line 2960, in _run_cell\n",
      "    return runner(coro)\n",
      "  File \"/Users/hiradekeishi/opt/anaconda3/envs/py3-TF2.0/lib/python3.7/site-packages/IPython/core/async_helpers.py\", line 78, in _pseudo_sync_runner\n",
      "    coro.send(None)\n",
      "  File \"/Users/hiradekeishi/opt/anaconda3/envs/py3-TF2.0/lib/python3.7/site-packages/IPython/core/interactiveshell.py\", line 3186, in run_cell_async\n",
      "    interactivity=interactivity, compiler=compiler, result=result)\n",
      "  File \"/Users/hiradekeishi/opt/anaconda3/envs/py3-TF2.0/lib/python3.7/site-packages/IPython/core/interactiveshell.py\", line 3396, in run_ast_nodes\n",
      "    self.showtraceback()\n",
      "  File \"/Users/hiradekeishi/opt/anaconda3/envs/py3-TF2.0/lib/python3.7/site-packages/IPython/core/interactiveshell.py\", line 2080, in showtraceback\n",
      "    value, tb, tb_offset=tb_offset)\n",
      "  File \"/Users/hiradekeishi/opt/anaconda3/envs/py3-TF2.0/lib/python3.7/site-packages/IPython/core/ultratb.py\", line 1368, in structured_traceback\n",
      "    self, etype, value, tb, tb_offset, number_of_lines_of_context)\n",
      "  File \"/Users/hiradekeishi/opt/anaconda3/envs/py3-TF2.0/lib/python3.7/site-packages/IPython/core/ultratb.py\", line 1268, in structured_traceback\n",
      "    self, etype, value, tb, tb_offset, number_of_lines_of_context\n",
      "  File \"/Users/hiradekeishi/opt/anaconda3/envs/py3-TF2.0/lib/python3.7/site-packages/IPython/core/ultratb.py\", line 1143, in structured_traceback\n",
      "    chained_exceptions_tb_offset)\n",
      "  File \"/Users/hiradekeishi/opt/anaconda3/envs/py3-TF2.0/lib/python3.7/site-packages/IPython/core/ultratb.py\", line 1082, in format_exception_as_a_whole\n",
      "    last_unique, recursion_repeat = find_recursion(orig_etype, evalue, records)\n",
      "  File \"/Users/hiradekeishi/opt/anaconda3/envs/py3-TF2.0/lib/python3.7/site-packages/IPython/core/ultratb.py\", line 382, in find_recursion\n",
      "    return len(records), 0\n",
      "TypeError: object of type 'NoneType' has no len()\n",
      "\n",
      "During handling of the above exception, another exception occurred:\n",
      "\n",
      "Traceback (most recent call last):\n",
      "  File \"/Users/hiradekeishi/opt/anaconda3/envs/py3-TF2.0/lib/python3.7/site-packages/IPython/core/interactiveshell.py\", line 2077, in showtraceback\n",
      "    stb = value._render_traceback_()\n",
      "AttributeError: 'TypeError' object has no attribute '_render_traceback_'\n",
      "\n",
      "During handling of the above exception, another exception occurred:\n",
      "\n",
      "Traceback (most recent call last):\n",
      "  File \"/Users/hiradekeishi/opt/anaconda3/envs/py3-TF2.0/lib/python3.7/site-packages/IPython/core/ultratb.py\", line 1101, in get_records\n",
      "    return _fixed_getinnerframes(etb, number_of_lines_of_context, tb_offset)\n",
      "  File \"/Users/hiradekeishi/opt/anaconda3/envs/py3-TF2.0/lib/python3.7/site-packages/IPython/core/ultratb.py\", line 248, in wrapped\n",
      "    return f(*args, **kwargs)\n",
      "  File \"/Users/hiradekeishi/opt/anaconda3/envs/py3-TF2.0/lib/python3.7/site-packages/IPython/core/ultratb.py\", line 281, in _fixed_getinnerframes\n",
      "    records = fix_frame_records_filenames(inspect.getinnerframes(etb, context))\n",
      "  File \"/Users/hiradekeishi/opt/anaconda3/envs/py3-TF2.0/lib/python3.7/inspect.py\", line 1502, in getinnerframes\n",
      "    frameinfo = (tb.tb_frame,) + getframeinfo(tb, context)\n",
      "  File \"/Users/hiradekeishi/opt/anaconda3/envs/py3-TF2.0/lib/python3.7/inspect.py\", line 1460, in getframeinfo\n",
      "    filename = getsourcefile(frame) or getfile(frame)\n",
      "  File \"/Users/hiradekeishi/opt/anaconda3/envs/py3-TF2.0/lib/python3.7/inspect.py\", line 696, in getsourcefile\n",
      "    if getattr(getmodule(object, filename), '__loader__', None) is not None:\n",
      "  File \"/Users/hiradekeishi/opt/anaconda3/envs/py3-TF2.0/lib/python3.7/inspect.py\", line 733, in getmodule\n",
      "    if ismodule(module) and hasattr(module, '__file__'):\n",
      "  File \"/Users/hiradekeishi/opt/anaconda3/envs/py3-TF2.0/lib/python3.7/site-packages/tensorflow/__init__.py\", line 50, in __getattr__\n",
      "    from ._api.v2 import bitwise\n",
      "  File \"/Users/hiradekeishi/opt/anaconda3/envs/py3-TF2.0/lib/python3.7/site-packages/tensorflow/__init__.py\", line 44, in _load\n",
      "  File \"/Users/hiradekeishi/opt/anaconda3/envs/py3-TF2.0/lib/python3.7/importlib/__init__.py\", line 127, in import_module\n",
      "    return _bootstrap._gcd_import(name[level:], package, level)\n",
      "  File \"<frozen importlib._bootstrap>\", line 1006, in _gcd_import\n",
      "  File \"<frozen importlib._bootstrap>\", line 983, in _find_and_load\n",
      "  File \"<frozen importlib._bootstrap>\", line 965, in _find_and_load_unlocked\n",
      "ModuleNotFoundError: No module named 'tensorflow_core.estimator'\n"
     ]
    }
   ],
   "source": [
    "#  検証用データを一時的に読み込み訓練\n",
    "npz = np.load('Audiobooks_data_train.npz')\n",
    "\n",
    "train_inputs = npz['inputs'].astype(np.feat)\n",
    "train_targets = npz['inputs'].astype(np.feat)\n",
    "\n",
    "# 検証用データを一時的に読み込み\n",
    "npz = np.load('Audiobooks_data_validation.npz')\n",
    "# 訓練用のデータを入力とターゲットに分けて変数に代入\n",
    "validation_inputs, validation_targets = npz['inputs'].astype(np.float), npz['targets'].astype(np.int)\n",
    "\n",
    "# テストデータを一時的に読み込み\n",
    "npz = np.load('Audiobooks_data_test.npz')\n",
    "# テスト用のデータを入力とターゲットに分けて変数に代入\n",
    "test_inputs, test_targets = npz['inputs'].astype(np.float), npz['targets'].astype(np.int)"
   ]
  },
  {
   "cell_type": "code",
   "execution_count": null,
   "id": "f35ab3ad",
   "metadata": {},
   "outputs": [
    {
     "name": "stderr",
     "output_type": "stream",
     "text": [
      "ERROR:root:Internal Python error in the inspect module.\n",
      "Below is the traceback from this internal error.\n",
      "\n",
      "ERROR:root:Internal Python error in the inspect module.\n",
      "Below is the traceback from this internal error.\n",
      "\n",
      "ERROR:root:Internal Python error in the inspect module.\n",
      "Below is the traceback from this internal error.\n",
      "\n"
     ]
    },
    {
     "name": "stdout",
     "output_type": "stream",
     "text": [
      "ERROR! Session/line number was not unique in database. History logging moved to new session 88\n",
      "Traceback (most recent call last):\n",
      "  File \"/Users/hiradekeishi/opt/anaconda3/envs/py3-TF2.0/lib/python3.7/site-packages/IPython/core/interactiveshell.py\", line 3457, in run_code\n",
      "    exec(code_obj, self.user_global_ns, self.user_ns)\n",
      "  File \"/var/folders/7_/5ly65s3j46zcgtgg9r0sjm940000gn/T/ipykernel_87487/1380709951.py\", line 30, in <module>\n",
      "    model.fit(train_inputs, # 訓練データの入力\n",
      "NameError: name 'train_inputs' is not defined\n",
      "\n",
      "During handling of the above exception, another exception occurred:\n",
      "\n",
      "Traceback (most recent call last):\n",
      "  File \"/Users/hiradekeishi/opt/anaconda3/envs/py3-TF2.0/lib/python3.7/site-packages/IPython/core/interactiveshell.py\", line 2077, in showtraceback\n",
      "    stb = value._render_traceback_()\n",
      "AttributeError: 'NameError' object has no attribute '_render_traceback_'\n",
      "\n",
      "During handling of the above exception, another exception occurred:\n",
      "\n",
      "Traceback (most recent call last):\n",
      "  File \"/Users/hiradekeishi/opt/anaconda3/envs/py3-TF2.0/lib/python3.7/site-packages/IPython/core/ultratb.py\", line 1101, in get_records\n",
      "    return _fixed_getinnerframes(etb, number_of_lines_of_context, tb_offset)\n",
      "  File \"/Users/hiradekeishi/opt/anaconda3/envs/py3-TF2.0/lib/python3.7/site-packages/IPython/core/ultratb.py\", line 248, in wrapped\n",
      "    return f(*args, **kwargs)\n",
      "  File \"/Users/hiradekeishi/opt/anaconda3/envs/py3-TF2.0/lib/python3.7/site-packages/IPython/core/ultratb.py\", line 281, in _fixed_getinnerframes\n",
      "    records = fix_frame_records_filenames(inspect.getinnerframes(etb, context))\n",
      "  File \"/Users/hiradekeishi/opt/anaconda3/envs/py3-TF2.0/lib/python3.7/inspect.py\", line 1502, in getinnerframes\n",
      "    frameinfo = (tb.tb_frame,) + getframeinfo(tb, context)\n",
      "  File \"/Users/hiradekeishi/opt/anaconda3/envs/py3-TF2.0/lib/python3.7/inspect.py\", line 1460, in getframeinfo\n",
      "    filename = getsourcefile(frame) or getfile(frame)\n",
      "  File \"/Users/hiradekeishi/opt/anaconda3/envs/py3-TF2.0/lib/python3.7/inspect.py\", line 696, in getsourcefile\n",
      "    if getattr(getmodule(object, filename), '__loader__', None) is not None:\n",
      "  File \"/Users/hiradekeishi/opt/anaconda3/envs/py3-TF2.0/lib/python3.7/inspect.py\", line 733, in getmodule\n",
      "    if ismodule(module) and hasattr(module, '__file__'):\n",
      "  File \"/Users/hiradekeishi/opt/anaconda3/envs/py3-TF2.0/lib/python3.7/site-packages/tensorflow/__init__.py\", line 50, in __getattr__\n",
      "    from ._api.v2 import bitwise\n",
      "  File \"/Users/hiradekeishi/opt/anaconda3/envs/py3-TF2.0/lib/python3.7/site-packages/tensorflow/__init__.py\", line 44, in _load\n",
      "  File \"/Users/hiradekeishi/opt/anaconda3/envs/py3-TF2.0/lib/python3.7/importlib/__init__.py\", line 127, in import_module\n",
      "    return _bootstrap._gcd_import(name[level:], package, level)\n",
      "  File \"<frozen importlib._bootstrap>\", line 1006, in _gcd_import\n",
      "  File \"<frozen importlib._bootstrap>\", line 983, in _find_and_load\n",
      "  File \"<frozen importlib._bootstrap>\", line 965, in _find_and_load_unlocked\n",
      "ModuleNotFoundError: No module named 'tensorflow_core.estimator'\n",
      "Traceback (most recent call last):\n",
      "  File \"/Users/hiradekeishi/opt/anaconda3/envs/py3-TF2.0/lib/python3.7/site-packages/IPython/core/interactiveshell.py\", line 3457, in run_code\n",
      "    exec(code_obj, self.user_global_ns, self.user_ns)\n",
      "  File \"/var/folders/7_/5ly65s3j46zcgtgg9r0sjm940000gn/T/ipykernel_87487/1380709951.py\", line 30, in <module>\n",
      "    model.fit(train_inputs, # 訓練データの入力\n",
      "NameError: name 'train_inputs' is not defined\n",
      "\n",
      "During handling of the above exception, another exception occurred:\n",
      "\n",
      "Traceback (most recent call last):\n",
      "  File \"/Users/hiradekeishi/opt/anaconda3/envs/py3-TF2.0/lib/python3.7/site-packages/IPython/core/interactiveshell.py\", line 2077, in showtraceback\n",
      "    stb = value._render_traceback_()\n",
      "AttributeError: 'NameError' object has no attribute '_render_traceback_'\n",
      "\n",
      "During handling of the above exception, another exception occurred:\n",
      "\n",
      "Traceback (most recent call last):\n",
      "  File \"/Users/hiradekeishi/opt/anaconda3/envs/py3-TF2.0/lib/python3.7/site-packages/IPython/core/interactiveshell.py\", line 3377, in run_ast_nodes\n",
      "    if (await self.run_code(code, result,  async_=asy)):\n",
      "  File \"/Users/hiradekeishi/opt/anaconda3/envs/py3-TF2.0/lib/python3.7/site-packages/IPython/core/interactiveshell.py\", line 3474, in run_code\n",
      "    self.showtraceback(running_compiled_code=True)\n",
      "  File \"/Users/hiradekeishi/opt/anaconda3/envs/py3-TF2.0/lib/python3.7/site-packages/IPython/core/interactiveshell.py\", line 2080, in showtraceback\n",
      "    value, tb, tb_offset=tb_offset)\n",
      "  File \"/Users/hiradekeishi/opt/anaconda3/envs/py3-TF2.0/lib/python3.7/site-packages/IPython/core/ultratb.py\", line 1368, in structured_traceback\n",
      "    self, etype, value, tb, tb_offset, number_of_lines_of_context)\n",
      "  File \"/Users/hiradekeishi/opt/anaconda3/envs/py3-TF2.0/lib/python3.7/site-packages/IPython/core/ultratb.py\", line 1268, in structured_traceback\n",
      "    self, etype, value, tb, tb_offset, number_of_lines_of_context\n",
      "  File \"/Users/hiradekeishi/opt/anaconda3/envs/py3-TF2.0/lib/python3.7/site-packages/IPython/core/ultratb.py\", line 1125, in structured_traceback\n",
      "    tb_offset)\n",
      "  File \"/Users/hiradekeishi/opt/anaconda3/envs/py3-TF2.0/lib/python3.7/site-packages/IPython/core/ultratb.py\", line 1082, in format_exception_as_a_whole\n",
      "    last_unique, recursion_repeat = find_recursion(orig_etype, evalue, records)\n",
      "  File \"/Users/hiradekeishi/opt/anaconda3/envs/py3-TF2.0/lib/python3.7/site-packages/IPython/core/ultratb.py\", line 382, in find_recursion\n",
      "    return len(records), 0\n",
      "TypeError: object of type 'NoneType' has no len()\n",
      "\n",
      "During handling of the above exception, another exception occurred:\n",
      "\n",
      "Traceback (most recent call last):\n",
      "  File \"/Users/hiradekeishi/opt/anaconda3/envs/py3-TF2.0/lib/python3.7/site-packages/IPython/core/interactiveshell.py\", line 2077, in showtraceback\n",
      "    stb = value._render_traceback_()\n",
      "AttributeError: 'TypeError' object has no attribute '_render_traceback_'\n",
      "\n",
      "During handling of the above exception, another exception occurred:\n",
      "\n",
      "Traceback (most recent call last):\n",
      "  File \"/Users/hiradekeishi/opt/anaconda3/envs/py3-TF2.0/lib/python3.7/site-packages/IPython/core/ultratb.py\", line 1101, in get_records\n",
      "    return _fixed_getinnerframes(etb, number_of_lines_of_context, tb_offset)\n",
      "  File \"/Users/hiradekeishi/opt/anaconda3/envs/py3-TF2.0/lib/python3.7/site-packages/IPython/core/ultratb.py\", line 248, in wrapped\n",
      "    return f(*args, **kwargs)\n",
      "  File \"/Users/hiradekeishi/opt/anaconda3/envs/py3-TF2.0/lib/python3.7/site-packages/IPython/core/ultratb.py\", line 281, in _fixed_getinnerframes\n",
      "    records = fix_frame_records_filenames(inspect.getinnerframes(etb, context))\n",
      "  File \"/Users/hiradekeishi/opt/anaconda3/envs/py3-TF2.0/lib/python3.7/inspect.py\", line 1502, in getinnerframes\n",
      "    frameinfo = (tb.tb_frame,) + getframeinfo(tb, context)\n",
      "  File \"/Users/hiradekeishi/opt/anaconda3/envs/py3-TF2.0/lib/python3.7/inspect.py\", line 1460, in getframeinfo\n",
      "    filename = getsourcefile(frame) or getfile(frame)\n",
      "  File \"/Users/hiradekeishi/opt/anaconda3/envs/py3-TF2.0/lib/python3.7/inspect.py\", line 696, in getsourcefile\n",
      "    if getattr(getmodule(object, filename), '__loader__', None) is not None:\n",
      "  File \"/Users/hiradekeishi/opt/anaconda3/envs/py3-TF2.0/lib/python3.7/inspect.py\", line 733, in getmodule\n",
      "    if ismodule(module) and hasattr(module, '__file__'):\n",
      "  File \"/Users/hiradekeishi/opt/anaconda3/envs/py3-TF2.0/lib/python3.7/site-packages/tensorflow/__init__.py\", line 50, in __getattr__\n",
      "    from ._api.v2 import bitwise\n",
      "  File \"/Users/hiradekeishi/opt/anaconda3/envs/py3-TF2.0/lib/python3.7/site-packages/tensorflow/__init__.py\", line 44, in _load\n",
      "  File \"/Users/hiradekeishi/opt/anaconda3/envs/py3-TF2.0/lib/python3.7/importlib/__init__.py\", line 127, in import_module\n",
      "    return _bootstrap._gcd_import(name[level:], package, level)\n",
      "  File \"<frozen importlib._bootstrap>\", line 1006, in _gcd_import\n",
      "  File \"<frozen importlib._bootstrap>\", line 983, in _find_and_load\n",
      "  File \"<frozen importlib._bootstrap>\", line 965, in _find_and_load_unlocked\n",
      "ModuleNotFoundError: No module named 'tensorflow_core.estimator'\n",
      "Traceback (most recent call last):\n",
      "  File \"/Users/hiradekeishi/opt/anaconda3/envs/py3-TF2.0/lib/python3.7/site-packages/IPython/core/interactiveshell.py\", line 3457, in run_code\n",
      "    exec(code_obj, self.user_global_ns, self.user_ns)\n",
      "  File \"/var/folders/7_/5ly65s3j46zcgtgg9r0sjm940000gn/T/ipykernel_87487/1380709951.py\", line 30, in <module>\n",
      "    model.fit(train_inputs, # 訓練データの入力\n",
      "NameError: name 'train_inputs' is not defined\n",
      "\n",
      "During handling of the above exception, another exception occurred:\n",
      "\n",
      "Traceback (most recent call last):\n",
      "  File \"/Users/hiradekeishi/opt/anaconda3/envs/py3-TF2.0/lib/python3.7/site-packages/IPython/core/interactiveshell.py\", line 2077, in showtraceback\n",
      "    stb = value._render_traceback_()\n",
      "AttributeError: 'NameError' object has no attribute '_render_traceback_'\n",
      "\n",
      "During handling of the above exception, another exception occurred:\n",
      "\n",
      "Traceback (most recent call last):\n",
      "  File \"/Users/hiradekeishi/opt/anaconda3/envs/py3-TF2.0/lib/python3.7/site-packages/IPython/core/interactiveshell.py\", line 3377, in run_ast_nodes\n",
      "    if (await self.run_code(code, result,  async_=asy)):\n",
      "  File \"/Users/hiradekeishi/opt/anaconda3/envs/py3-TF2.0/lib/python3.7/site-packages/IPython/core/interactiveshell.py\", line 3474, in run_code\n",
      "    self.showtraceback(running_compiled_code=True)\n",
      "  File \"/Users/hiradekeishi/opt/anaconda3/envs/py3-TF2.0/lib/python3.7/site-packages/IPython/core/interactiveshell.py\", line 2080, in showtraceback\n",
      "    value, tb, tb_offset=tb_offset)\n",
      "  File \"/Users/hiradekeishi/opt/anaconda3/envs/py3-TF2.0/lib/python3.7/site-packages/IPython/core/ultratb.py\", line 1368, in structured_traceback\n",
      "    self, etype, value, tb, tb_offset, number_of_lines_of_context)\n",
      "  File \"/Users/hiradekeishi/opt/anaconda3/envs/py3-TF2.0/lib/python3.7/site-packages/IPython/core/ultratb.py\", line 1268, in structured_traceback\n",
      "    self, etype, value, tb, tb_offset, number_of_lines_of_context\n",
      "  File \"/Users/hiradekeishi/opt/anaconda3/envs/py3-TF2.0/lib/python3.7/site-packages/IPython/core/ultratb.py\", line 1125, in structured_traceback\n",
      "    tb_offset)\n",
      "  File \"/Users/hiradekeishi/opt/anaconda3/envs/py3-TF2.0/lib/python3.7/site-packages/IPython/core/ultratb.py\", line 1082, in format_exception_as_a_whole\n",
      "    last_unique, recursion_repeat = find_recursion(orig_etype, evalue, records)\n",
      "  File \"/Users/hiradekeishi/opt/anaconda3/envs/py3-TF2.0/lib/python3.7/site-packages/IPython/core/ultratb.py\", line 382, in find_recursion\n",
      "    return len(records), 0\n",
      "TypeError: object of type 'NoneType' has no len()\n",
      "\n",
      "During handling of the above exception, another exception occurred:\n",
      "\n",
      "Traceback (most recent call last):\n",
      "  File \"/Users/hiradekeishi/opt/anaconda3/envs/py3-TF2.0/lib/python3.7/site-packages/IPython/core/interactiveshell.py\", line 2077, in showtraceback\n",
      "    stb = value._render_traceback_()\n",
      "AttributeError: 'TypeError' object has no attribute '_render_traceback_'\n",
      "\n",
      "During handling of the above exception, another exception occurred:\n",
      "\n",
      "Traceback (most recent call last):\n",
      "  File \"/Users/hiradekeishi/opt/anaconda3/envs/py3-TF2.0/lib/python3.7/site-packages/IPython/core/interactiveshell.py\", line 2960, in _run_cell\n",
      "    return runner(coro)\n",
      "  File \"/Users/hiradekeishi/opt/anaconda3/envs/py3-TF2.0/lib/python3.7/site-packages/IPython/core/async_helpers.py\", line 78, in _pseudo_sync_runner\n",
      "    coro.send(None)\n",
      "  File \"/Users/hiradekeishi/opt/anaconda3/envs/py3-TF2.0/lib/python3.7/site-packages/IPython/core/interactiveshell.py\", line 3186, in run_cell_async\n",
      "    interactivity=interactivity, compiler=compiler, result=result)\n",
      "  File \"/Users/hiradekeishi/opt/anaconda3/envs/py3-TF2.0/lib/python3.7/site-packages/IPython/core/interactiveshell.py\", line 3396, in run_ast_nodes\n",
      "    self.showtraceback()\n",
      "  File \"/Users/hiradekeishi/opt/anaconda3/envs/py3-TF2.0/lib/python3.7/site-packages/IPython/core/interactiveshell.py\", line 2080, in showtraceback\n",
      "    value, tb, tb_offset=tb_offset)\n",
      "  File \"/Users/hiradekeishi/opt/anaconda3/envs/py3-TF2.0/lib/python3.7/site-packages/IPython/core/ultratb.py\", line 1368, in structured_traceback\n",
      "    self, etype, value, tb, tb_offset, number_of_lines_of_context)\n",
      "  File \"/Users/hiradekeishi/opt/anaconda3/envs/py3-TF2.0/lib/python3.7/site-packages/IPython/core/ultratb.py\", line 1268, in structured_traceback\n",
      "    self, etype, value, tb, tb_offset, number_of_lines_of_context\n",
      "  File \"/Users/hiradekeishi/opt/anaconda3/envs/py3-TF2.0/lib/python3.7/site-packages/IPython/core/ultratb.py\", line 1143, in structured_traceback\n",
      "    chained_exceptions_tb_offset)\n",
      "  File \"/Users/hiradekeishi/opt/anaconda3/envs/py3-TF2.0/lib/python3.7/site-packages/IPython/core/ultratb.py\", line 1082, in format_exception_as_a_whole\n",
      "    last_unique, recursion_repeat = find_recursion(orig_etype, evalue, records)\n",
      "  File \"/Users/hiradekeishi/opt/anaconda3/envs/py3-TF2.0/lib/python3.7/site-packages/IPython/core/ultratb.py\", line 382, in find_recursion\n",
      "    return len(records), 0\n",
      "TypeError: object of type 'NoneType' has no len()\n",
      "\n",
      "During handling of the above exception, another exception occurred:\n",
      "\n",
      "Traceback (most recent call last):\n",
      "  File \"/Users/hiradekeishi/opt/anaconda3/envs/py3-TF2.0/lib/python3.7/site-packages/IPython/core/interactiveshell.py\", line 2077, in showtraceback\n",
      "    stb = value._render_traceback_()\n",
      "AttributeError: 'TypeError' object has no attribute '_render_traceback_'\n",
      "\n",
      "During handling of the above exception, another exception occurred:\n",
      "\n",
      "Traceback (most recent call last):\n",
      "  File \"/Users/hiradekeishi/opt/anaconda3/envs/py3-TF2.0/lib/python3.7/site-packages/IPython/core/ultratb.py\", line 1101, in get_records\n",
      "    return _fixed_getinnerframes(etb, number_of_lines_of_context, tb_offset)\n",
      "  File \"/Users/hiradekeishi/opt/anaconda3/envs/py3-TF2.0/lib/python3.7/site-packages/IPython/core/ultratb.py\", line 248, in wrapped\n",
      "    return f(*args, **kwargs)\n",
      "  File \"/Users/hiradekeishi/opt/anaconda3/envs/py3-TF2.0/lib/python3.7/site-packages/IPython/core/ultratb.py\", line 281, in _fixed_getinnerframes\n",
      "    records = fix_frame_records_filenames(inspect.getinnerframes(etb, context))\n",
      "  File \"/Users/hiradekeishi/opt/anaconda3/envs/py3-TF2.0/lib/python3.7/inspect.py\", line 1502, in getinnerframes\n",
      "    frameinfo = (tb.tb_frame,) + getframeinfo(tb, context)\n",
      "  File \"/Users/hiradekeishi/opt/anaconda3/envs/py3-TF2.0/lib/python3.7/inspect.py\", line 1460, in getframeinfo\n",
      "    filename = getsourcefile(frame) or getfile(frame)\n",
      "  File \"/Users/hiradekeishi/opt/anaconda3/envs/py3-TF2.0/lib/python3.7/inspect.py\", line 696, in getsourcefile\n",
      "    if getattr(getmodule(object, filename), '__loader__', None) is not None:\n",
      "  File \"/Users/hiradekeishi/opt/anaconda3/envs/py3-TF2.0/lib/python3.7/inspect.py\", line 733, in getmodule\n",
      "    if ismodule(module) and hasattr(module, '__file__'):\n",
      "  File \"/Users/hiradekeishi/opt/anaconda3/envs/py3-TF2.0/lib/python3.7/site-packages/tensorflow/__init__.py\", line 50, in __getattr__\n",
      "    from ._api.v2 import bitwise\n",
      "  File \"/Users/hiradekeishi/opt/anaconda3/envs/py3-TF2.0/lib/python3.7/site-packages/tensorflow/__init__.py\", line 44, in _load\n",
      "  File \"/Users/hiradekeishi/opt/anaconda3/envs/py3-TF2.0/lib/python3.7/importlib/__init__.py\", line 127, in import_module\n",
      "    return _bootstrap._gcd_import(name[level:], package, level)\n",
      "  File \"<frozen importlib._bootstrap>\", line 1006, in _gcd_import\n",
      "  File \"<frozen importlib._bootstrap>\", line 983, in _find_and_load\n",
      "  File \"<frozen importlib._bootstrap>\", line 965, in _find_and_load_unlocked\n",
      "ModuleNotFoundError: No module named 'tensorflow_core.estimator'\n"
     ]
    }
   ],
   "source": [
    "# 入力の数と出力の数を定義\n",
    "input_size = 10\n",
    "output_size = 2\n",
    "# 隠れ層のユニットの数を定義\n",
    "hidden_layer_size = 50\n",
    "    \n",
    "# モデルを作成\n",
    "model = tf.keras.Sequential([\n",
    "    tf.keras.layers.Dense(hidden_layer_size, activation='relu'), # 1番目の隠れ層\n",
    "    tf.keras.layers.Dense(hidden_layer_size, activation='relu'), # 2番目の隠れ層\n",
    "    tf.keras.layers.Dense(output_size, activation='softmax') # 出力層\n",
    "])\n",
    "\n",
    "\n",
    "# 損失関数と最適化アルゴリズムを定義\n",
    "model.compile(optimizer='adam', loss='sparse_categorical_crossentropy', metrics=['accuracy'])\n",
    "\n",
    "### 訓練\n",
    "\n",
    "# バッチサイズの設定\n",
    "batch_size = 100\n",
    "\n",
    "# 繰り返し回数の設定\n",
    "max_epochs = 100\n",
    "\n",
    "# アーリーストッピングの設定(patience->2回までなら損失関数がふえてok)\n",
    "early_stopping = tf.keras.callbacks.EarlyStopping(patience=2)\n",
    "\n",
    "# モデルにデータを挿入\n",
    "model.fit(train_inputs, # 訓練データの入力\n",
    "          train_targets, # 訓練データのターゲット\n",
    "          batch_size=batch_size, # バッチサイズ\n",
    "          epochs=max_epochs, # 繰り返し回数\n",
    "          callbacks=[early_stopping], # アーリーストッピング\n",
    "          validation_data=(validation_inputs, validation_targets), # 検証データの指定\n",
    "          verbose = 2 # 結果の見た目を変更\n",
    "          ) \n"
   ]
  },
  {
   "cell_type": "code",
   "execution_count": null,
   "id": "b238d152",
   "metadata": {},
   "outputs": [
    {
     "name": "stderr",
     "output_type": "stream",
     "text": [
      "ERROR:root:Internal Python error in the inspect module.\n",
      "Below is the traceback from this internal error.\n",
      "\n",
      "ERROR:root:Internal Python error in the inspect module.\n",
      "Below is the traceback from this internal error.\n",
      "\n",
      "ERROR:root:Internal Python error in the inspect module.\n",
      "Below is the traceback from this internal error.\n",
      "\n"
     ]
    },
    {
     "name": "stdout",
     "output_type": "stream",
     "text": [
      "ERROR! Session/line number was not unique inTraceback (most recent call last):\n",
      " database. History logging moved to new session 89\n",
      "  File \"/Users/hiradekeishi/opt/anaconda3/envs/py3-TF2.0/lib/python3.7/site-packages/IPython/core/interactiveshell.py\", line 3457, in run_code\n",
      "    exec(code_obj, self.user_global_ns, self.user_ns)\n",
      "  File \"/var/folders/7_/5ly65s3j46zcgtgg9r0sjm940000gn/T/ipykernel_87487/3029335762.py\", line 1, in <module>\n",
      "    test_loss, test_accuracy = model.evaluate(test_inputs, test_targets)\n",
      "NameError: name 'test_inputs' is not defined\n",
      "\n",
      "During handling of the above exception, another exception occurred:\n",
      "\n",
      "Traceback (most recent call last):\n",
      "  File \"/Users/hiradekeishi/opt/anaconda3/envs/py3-TF2.0/lib/python3.7/site-packages/IPython/core/interactiveshell.py\", line 2077, in showtraceback\n",
      "    stb = value._render_traceback_()\n",
      "AttributeError: 'NameError' object has no attribute '_render_traceback_'\n",
      "\n",
      "During handling of the above exception, another exception occurred:\n",
      "\n",
      "Traceback (most recent call last):\n",
      "  File \"/Users/hiradekeishi/opt/anaconda3/envs/py3-TF2.0/lib/python3.7/site-packages/IPython/core/ultratb.py\", line 1101, in get_records\n",
      "    return _fixed_getinnerframes(etb, number_of_lines_of_context, tb_offset)\n",
      "  File \"/Users/hiradekeishi/opt/anaconda3/envs/py3-TF2.0/lib/python3.7/site-packages/IPython/core/ultratb.py\", line 248, in wrapped\n",
      "    return f(*args, **kwargs)\n",
      "  File \"/Users/hiradekeishi/opt/anaconda3/envs/py3-TF2.0/lib/python3.7/site-packages/IPython/core/ultratb.py\", line 281, in _fixed_getinnerframes\n",
      "    records = fix_frame_records_filenames(inspect.getinnerframes(etb, context))\n",
      "  File \"/Users/hiradekeishi/opt/anaconda3/envs/py3-TF2.0/lib/python3.7/inspect.py\", line 1502, in getinnerframes\n",
      "    frameinfo = (tb.tb_frame,) + getframeinfo(tb, context)\n",
      "  File \"/Users/hiradekeishi/opt/anaconda3/envs/py3-TF2.0/lib/python3.7/inspect.py\", line 1460, in getframeinfo\n",
      "    filename = getsourcefile(frame) or getfile(frame)\n",
      "  File \"/Users/hiradekeishi/opt/anaconda3/envs/py3-TF2.0/lib/python3.7/inspect.py\", line 696, in getsourcefile\n",
      "    if getattr(getmodule(object, filename), '__loader__', None) is not None:\n",
      "  File \"/Users/hiradekeishi/opt/anaconda3/envs/py3-TF2.0/lib/python3.7/inspect.py\", line 733, in getmodule\n",
      "    if ismodule(module) and hasattr(module, '__file__'):\n",
      "  File \"/Users/hiradekeishi/opt/anaconda3/envs/py3-TF2.0/lib/python3.7/site-packages/tensorflow/__init__.py\", line 50, in __getattr__\n",
      "    from ._api.v2 import bitwise\n",
      "  File \"/Users/hiradekeishi/opt/anaconda3/envs/py3-TF2.0/lib/python3.7/site-packages/tensorflow/__init__.py\", line 44, in _load\n",
      "  File \"/Users/hiradekeishi/opt/anaconda3/envs/py3-TF2.0/lib/python3.7/importlib/__init__.py\", line 127, in import_module\n",
      "    return _bootstrap._gcd_import(name[level:], package, level)\n",
      "  File \"<frozen importlib._bootstrap>\", line 1006, in _gcd_import\n",
      "  File \"<frozen importlib._bootstrap>\", line 983, in _find_and_load\n",
      "  File \"<frozen importlib._bootstrap>\", line 965, in _find_and_load_unlocked\n",
      "ModuleNotFoundError: No module named 'tensorflow_core.estimator'\n",
      "Traceback (most recent call last):\n",
      "  File \"/Users/hiradekeishi/opt/anaconda3/envs/py3-TF2.0/lib/python3.7/site-packages/IPython/core/interactiveshell.py\", line 3457, in run_code\n",
      "    exec(code_obj, self.user_global_ns, self.user_ns)\n",
      "  File \"/var/folders/7_/5ly65s3j46zcgtgg9r0sjm940000gn/T/ipykernel_87487/3029335762.py\", line 1, in <module>\n",
      "    test_loss, test_accuracy = model.evaluate(test_inputs, test_targets)\n",
      "NameError: name 'test_inputs' is not defined\n",
      "\n",
      "During handling of the above exception, another exception occurred:\n",
      "\n",
      "Traceback (most recent call last):\n",
      "  File \"/Users/hiradekeishi/opt/anaconda3/envs/py3-TF2.0/lib/python3.7/site-packages/IPython/core/interactiveshell.py\", line 2077, in showtraceback\n",
      "    stb = value._render_traceback_()\n",
      "AttributeError: 'NameError' object has no attribute '_render_traceback_'\n",
      "\n",
      "During handling of the above exception, another exception occurred:\n",
      "\n",
      "Traceback (most recent call last):\n",
      "  File \"/Users/hiradekeishi/opt/anaconda3/envs/py3-TF2.0/lib/python3.7/site-packages/IPython/core/interactiveshell.py\", line 3377, in run_ast_nodes\n",
      "    if (await self.run_code(code, result,  async_=asy)):\n",
      "  File \"/Users/hiradekeishi/opt/anaconda3/envs/py3-TF2.0/lib/python3.7/site-packages/IPython/core/interactiveshell.py\", line 3474, in run_code\n",
      "    self.showtraceback(running_compiled_code=True)\n",
      "  File \"/Users/hiradekeishi/opt/anaconda3/envs/py3-TF2.0/lib/python3.7/site-packages/IPython/core/interactiveshell.py\", line 2080, in showtraceback\n",
      "    value, tb, tb_offset=tb_offset)\n",
      "  File \"/Users/hiradekeishi/opt/anaconda3/envs/py3-TF2.0/lib/python3.7/site-packages/IPython/core/ultratb.py\", line 1368, in structured_traceback\n",
      "    self, etype, value, tb, tb_offset, number_of_lines_of_context)\n",
      "  File \"/Users/hiradekeishi/opt/anaconda3/envs/py3-TF2.0/lib/python3.7/site-packages/IPython/core/ultratb.py\", line 1268, in structured_traceback\n",
      "    self, etype, value, tb, tb_offset, number_of_lines_of_context\n",
      "  File \"/Users/hiradekeishi/opt/anaconda3/envs/py3-TF2.0/lib/python3.7/site-packages/IPython/core/ultratb.py\", line 1125, in structured_traceback\n",
      "    tb_offset)\n",
      "  File \"/Users/hiradekeishi/opt/anaconda3/envs/py3-TF2.0/lib/python3.7/site-packages/IPython/core/ultratb.py\", line 1082, in format_exception_as_a_whole\n",
      "    last_unique, recursion_repeat = find_recursion(orig_etype, evalue, records)\n",
      "  File \"/Users/hiradekeishi/opt/anaconda3/envs/py3-TF2.0/lib/python3.7/site-packages/IPython/core/ultratb.py\", line 382, in find_recursion\n",
      "    return len(records), 0\n",
      "TypeError: object of type 'NoneType' has no len()\n",
      "\n",
      "During handling of the above exception, another exception occurred:\n",
      "\n",
      "Traceback (most recent call last):\n",
      "  File \"/Users/hiradekeishi/opt/anaconda3/envs/py3-TF2.0/lib/python3.7/site-packages/IPython/core/interactiveshell.py\", line 2077, in showtraceback\n",
      "    stb = value._render_traceback_()\n",
      "AttributeError: 'TypeError' object has no attribute '_render_traceback_'\n",
      "\n",
      "During handling of the above exception, another exception occurred:\n",
      "\n",
      "Traceback (most recent call last):\n",
      "  File \"/Users/hiradekeishi/opt/anaconda3/envs/py3-TF2.0/lib/python3.7/site-packages/IPython/core/ultratb.py\", line 1101, in get_records\n",
      "    return _fixed_getinnerframes(etb, number_of_lines_of_context, tb_offset)\n",
      "  File \"/Users/hiradekeishi/opt/anaconda3/envs/py3-TF2.0/lib/python3.7/site-packages/IPython/core/ultratb.py\", line 248, in wrapped\n",
      "    return f(*args, **kwargs)\n",
      "  File \"/Users/hiradekeishi/opt/anaconda3/envs/py3-TF2.0/lib/python3.7/site-packages/IPython/core/ultratb.py\", line 281, in _fixed_getinnerframes\n",
      "    records = fix_frame_records_filenames(inspect.getinnerframes(etb, context))\n",
      "  File \"/Users/hiradekeishi/opt/anaconda3/envs/py3-TF2.0/lib/python3.7/inspect.py\", line 1502, in getinnerframes\n",
      "    frameinfo = (tb.tb_frame,) + getframeinfo(tb, context)\n",
      "  File \"/Users/hiradekeishi/opt/anaconda3/envs/py3-TF2.0/lib/python3.7/inspect.py\", line 1460, in getframeinfo\n",
      "    filename = getsourcefile(frame) or getfile(frame)\n",
      "  File \"/Users/hiradekeishi/opt/anaconda3/envs/py3-TF2.0/lib/python3.7/inspect.py\", line 696, in getsourcefile\n",
      "    if getattr(getmodule(object, filename), '__loader__', None) is not None:\n",
      "  File \"/Users/hiradekeishi/opt/anaconda3/envs/py3-TF2.0/lib/python3.7/inspect.py\", line 733, in getmodule\n",
      "    if ismodule(module) and hasattr(module, '__file__'):\n",
      "  File \"/Users/hiradekeishi/opt/anaconda3/envs/py3-TF2.0/lib/python3.7/site-packages/tensorflow/__init__.py\", line 50, in __getattr__\n",
      "    from ._api.v2 import bitwise\n",
      "  File \"/Users/hiradekeishi/opt/anaconda3/envs/py3-TF2.0/lib/python3.7/site-packages/tensorflow/__init__.py\", line 44, in _load\n",
      "  File \"/Users/hiradekeishi/opt/anaconda3/envs/py3-TF2.0/lib/python3.7/importlib/__init__.py\", line 127, in import_module\n",
      "    return _bootstrap._gcd_import(name[level:], package, level)\n",
      "  File \"<frozen importlib._bootstrap>\", line 1006, in _gcd_import\n",
      "  File \"<frozen importlib._bootstrap>\", line 983, in _find_and_load\n",
      "  File \"<frozen importlib._bootstrap>\", line 965, in _find_and_load_unlocked\n",
      "ModuleNotFoundError: No module named 'tensorflow_core.estimator'\n",
      "Traceback (most recent call last):\n",
      "  File \"/Users/hiradekeishi/opt/anaconda3/envs/py3-TF2.0/lib/python3.7/site-packages/IPython/core/interactiveshell.py\", line 3457, in run_code\n",
      "    exec(code_obj, self.user_global_ns, self.user_ns)\n",
      "  File \"/var/folders/7_/5ly65s3j46zcgtgg9r0sjm940000gn/T/ipykernel_87487/3029335762.py\", line 1, in <module>\n",
      "    test_loss, test_accuracy = model.evaluate(test_inputs, test_targets)\n",
      "NameError: name 'test_inputs' is not defined\n",
      "\n",
      "During handling of the above exception, another exception occurred:\n",
      "\n",
      "Traceback (most recent call last):\n",
      "  File \"/Users/hiradekeishi/opt/anaconda3/envs/py3-TF2.0/lib/python3.7/site-packages/IPython/core/interactiveshell.py\", line 2077, in showtraceback\n",
      "    stb = value._render_traceback_()\n",
      "AttributeError: 'NameError' object has no attribute '_render_traceback_'\n",
      "\n",
      "During handling of the above exception, another exception occurred:\n",
      "\n",
      "Traceback (most recent call last):\n",
      "  File \"/Users/hiradekeishi/opt/anaconda3/envs/py3-TF2.0/lib/python3.7/site-packages/IPython/core/interactiveshell.py\", line 3377, in run_ast_nodes\n",
      "    if (await self.run_code(code, result,  async_=asy)):\n",
      "  File \"/Users/hiradekeishi/opt/anaconda3/envs/py3-TF2.0/lib/python3.7/site-packages/IPython/core/interactiveshell.py\", line 3474, in run_code\n",
      "    self.showtraceback(running_compiled_code=True)\n",
      "  File \"/Users/hiradekeishi/opt/anaconda3/envs/py3-TF2.0/lib/python3.7/site-packages/IPython/core/interactiveshell.py\", line 2080, in showtraceback\n",
      "    value, tb, tb_offset=tb_offset)\n",
      "  File \"/Users/hiradekeishi/opt/anaconda3/envs/py3-TF2.0/lib/python3.7/site-packages/IPython/core/ultratb.py\", line 1368, in structured_traceback\n",
      "    self, etype, value, tb, tb_offset, number_of_lines_of_context)\n",
      "  File \"/Users/hiradekeishi/opt/anaconda3/envs/py3-TF2.0/lib/python3.7/site-packages/IPython/core/ultratb.py\", line 1268, in structured_traceback\n",
      "    self, etype, value, tb, tb_offset, number_of_lines_of_context\n",
      "  File \"/Users/hiradekeishi/opt/anaconda3/envs/py3-TF2.0/lib/python3.7/site-packages/IPython/core/ultratb.py\", line 1125, in structured_traceback\n",
      "    tb_offset)\n",
      "  File \"/Users/hiradekeishi/opt/anaconda3/envs/py3-TF2.0/lib/python3.7/site-packages/IPython/core/ultratb.py\", line 1082, in format_exception_as_a_whole\n",
      "    last_unique, recursion_repeat = find_recursion(orig_etype, evalue, records)\n",
      "  File \"/Users/hiradekeishi/opt/anaconda3/envs/py3-TF2.0/lib/python3.7/site-packages/IPython/core/ultratb.py\", line 382, in find_recursion\n",
      "    return len(records), 0\n",
      "TypeError: object of type 'NoneType' has no len()\n",
      "\n",
      "During handling of the above exception, another exception occurred:\n",
      "\n",
      "Traceback (most recent call last):\n",
      "  File \"/Users/hiradekeishi/opt/anaconda3/envs/py3-TF2.0/lib/python3.7/site-packages/IPython/core/interactiveshell.py\", line 2077, in showtraceback\n",
      "    stb = value._render_traceback_()\n",
      "AttributeError: 'TypeError' object has no attribute '_render_traceback_'\n",
      "\n",
      "During handling of the above exception, another exception occurred:\n",
      "\n",
      "Traceback (most recent call last):\n",
      "  File \"/Users/hiradekeishi/opt/anaconda3/envs/py3-TF2.0/lib/python3.7/site-packages/IPython/core/interactiveshell.py\", line 2960, in _run_cell\n",
      "    return runner(coro)\n",
      "  File \"/Users/hiradekeishi/opt/anaconda3/envs/py3-TF2.0/lib/python3.7/site-packages/IPython/core/async_helpers.py\", line 78, in _pseudo_sync_runner\n",
      "    coro.send(None)\n",
      "  File \"/Users/hiradekeishi/opt/anaconda3/envs/py3-TF2.0/lib/python3.7/site-packages/IPython/core/interactiveshell.py\", line 3186, in run_cell_async\n",
      "    interactivity=interactivity, compiler=compiler, result=result)\n",
      "  File \"/Users/hiradekeishi/opt/anaconda3/envs/py3-TF2.0/lib/python3.7/site-packages/IPython/core/interactiveshell.py\", line 3396, in run_ast_nodes\n",
      "    self.showtraceback()\n",
      "  File \"/Users/hiradekeishi/opt/anaconda3/envs/py3-TF2.0/lib/python3.7/site-packages/IPython/core/interactiveshell.py\", line 2080, in showtraceback\n",
      "    value, tb, tb_offset=tb_offset)\n",
      "  File \"/Users/hiradekeishi/opt/anaconda3/envs/py3-TF2.0/lib/python3.7/site-packages/IPython/core/ultratb.py\", line 1368, in structured_traceback\n",
      "    self, etype, value, tb, tb_offset, number_of_lines_of_context)\n",
      "  File \"/Users/hiradekeishi/opt/anaconda3/envs/py3-TF2.0/lib/python3.7/site-packages/IPython/core/ultratb.py\", line 1268, in structured_traceback\n",
      "    self, etype, value, tb, tb_offset, number_of_lines_of_context\n",
      "  File \"/Users/hiradekeishi/opt/anaconda3/envs/py3-TF2.0/lib/python3.7/site-packages/IPython/core/ultratb.py\", line 1143, in structured_traceback\n",
      "    chained_exceptions_tb_offset)\n",
      "  File \"/Users/hiradekeishi/opt/anaconda3/envs/py3-TF2.0/lib/python3.7/site-packages/IPython/core/ultratb.py\", line 1082, in format_exception_as_a_whole\n",
      "    last_unique, recursion_repeat = find_recursion(orig_etype, evalue, records)\n",
      "  File \"/Users/hiradekeishi/opt/anaconda3/envs/py3-TF2.0/lib/python3.7/site-packages/IPython/core/ultratb.py\", line 382, in find_recursion\n",
      "    return len(records), 0\n",
      "TypeError: object of type 'NoneType' has no len()\n",
      "\n",
      "During handling of the above exception, another exception occurred:\n",
      "\n",
      "Traceback (most recent call last):\n",
      "  File \"/Users/hiradekeishi/opt/anaconda3/envs/py3-TF2.0/lib/python3.7/site-packages/IPython/core/interactiveshell.py\", line 2077, in showtraceback\n",
      "    stb = value._render_traceback_()\n",
      "AttributeError: 'TypeError' object has no attribute '_render_traceback_'\n",
      "\n",
      "During handling of the above exception, another exception occurred:\n",
      "\n",
      "Traceback (most recent call last):\n",
      "  File \"/Users/hiradekeishi/opt/anaconda3/envs/py3-TF2.0/lib/python3.7/site-packages/IPython/core/ultratb.py\", line 1101, in get_records\n",
      "    return _fixed_getinnerframes(etb, number_of_lines_of_context, tb_offset)\n",
      "  File \"/Users/hiradekeishi/opt/anaconda3/envs/py3-TF2.0/lib/python3.7/site-packages/IPython/core/ultratb.py\", line 248, in wrapped\n",
      "    return f(*args, **kwargs)\n",
      "  File \"/Users/hiradekeishi/opt/anaconda3/envs/py3-TF2.0/lib/python3.7/site-packages/IPython/core/ultratb.py\", line 281, in _fixed_getinnerframes\n",
      "    records = fix_frame_records_filenames(inspect.getinnerframes(etb, context))\n",
      "  File \"/Users/hiradekeishi/opt/anaconda3/envs/py3-TF2.0/lib/python3.7/inspect.py\", line 1502, in getinnerframes\n",
      "    frameinfo = (tb.tb_frame,) + getframeinfo(tb, context)\n",
      "  File \"/Users/hiradekeishi/opt/anaconda3/envs/py3-TF2.0/lib/python3.7/inspect.py\", line 1460, in getframeinfo\n",
      "    filename = getsourcefile(frame) or getfile(frame)\n",
      "  File \"/Users/hiradekeishi/opt/anaconda3/envs/py3-TF2.0/lib/python3.7/inspect.py\", line 696, in getsourcefile\n",
      "    if getattr(getmodule(object, filename), '__loader__', None) is not None:\n",
      "  File \"/Users/hiradekeishi/opt/anaconda3/envs/py3-TF2.0/lib/python3.7/inspect.py\", line 733, in getmodule\n",
      "    if ismodule(module) and hasattr(module, '__file__'):\n",
      "  File \"/Users/hiradekeishi/opt/anaconda3/envs/py3-TF2.0/lib/python3.7/site-packages/tensorflow/__init__.py\", line 50, in __getattr__\n",
      "    from ._api.v2 import bitwise\n",
      "  File \"/Users/hiradekeishi/opt/anaconda3/envs/py3-TF2.0/lib/python3.7/site-packages/tensorflow/__init__.py\", line 44, in _load\n",
      "  File \"/Users/hiradekeishi/opt/anaconda3/envs/py3-TF2.0/lib/python3.7/importlib/__init__.py\", line 127, in import_module\n",
      "    return _bootstrap._gcd_import(name[level:], package, level)\n",
      "  File \"<frozen importlib._bootstrap>\", line 1006, in _gcd_import\n",
      "  File \"<frozen importlib._bootstrap>\", line 983, in _find_and_load\n",
      "  File \"<frozen importlib._bootstrap>\", line 965, in _find_and_load_unlocked\n",
      "ModuleNotFoundError: No module named 'tensorflow_core.estimator'\n"
     ]
    }
   ],
   "source": [
    "test_loss, test_accuracy = model.evaluate(test_inputs, test_targets)"
   ]
  },
  {
   "cell_type": "code",
   "execution_count": null,
   "id": "fec9a024",
   "metadata": {},
   "outputs": [
    {
     "name": "stderr",
     "output_type": "stream",
     "text": [
      "ERROR:root:Internal Python error in the inspect module.\n",
      "Below is the traceback from this internal error.\n",
      "\n",
      "ERROR:root:Internal Python error in the inspect module.\n",
      "Below is the traceback from this internal error.\n",
      "\n",
      "ERROR:root:Internal Python error in the inspect module.\n",
      "Below is the traceback from this internal error.\n",
      "\n"
     ]
    },
    {
     "name": "stdout",
     "output_type": "stream",
     "text": [
      "ERROR! Session/line number was not unique inTraceback (most recent call last):\n",
      "  File \"/Users/hiradekeishi/opt/anaconda3/envs/py3-TF2.0/lib/python3.7/site-packages/IPython/core/interactiveshell.py\", line 3457, in run_code\n",
      "    exec(code_obj, self.user_global_ns, self.user_ns)\n",
      "  File \"/var/folders/7_/5ly65s3j46zcgtgg9r0sjm940000gn/T/ipykernel_87487/1320733958.py\", line 1, in <module>\n",
      "    print('\\nTest loss: {0:.2f}. Test accuracy: {1:.2f}%'.format(test_loss, test_accuracy*100.))\n",
      "NameError: name 'test_loss' is not defined\n",
      "\n",
      "During handling of the above exception, another exception occurred:\n",
      "\n",
      "Traceback (most recent call last):\n",
      "  File \"/Users/hiradekeishi/opt/anaconda3/envs/py3-TF2.0/lib/python3.7/site-packages/IPython/core/interactiveshell.py\", line 2077, in showtraceback\n",
      "    stb = value._render_traceback_()\n",
      "AttributeError: 'NameError' object has no attribute '_render_traceback_'\n",
      "\n",
      "During handling of the above exception, another exception occurred:\n",
      "\n",
      "Traceback (most recent call last):\n",
      "  File \"/Users/hiradekeishi/opt/anaconda3/envs/py3-TF2.0/lib/python3.7/site-packages/IPython/core/ultratb.py\", line 1101, in get_records\n",
      "    return _fixed_getinnerframes(etb, number_of_lines_of_context, tb_offset)\n",
      "  File \"/Users/hiradekeishi/opt/anaconda3/envs/py3-TF2.0/lib/python3.7/site-packages/IPython/core/ultratb.py\", line 248, in wrapped\n",
      "    return f(*args, **kwargs)\n",
      "  File \"/Users/hiradekeishi/opt/anaconda3/envs/py3-TF2.0/lib/python3.7/site-packages/IPython/core/ultratb.py\", line 281, in _fixed_getinnerframes\n",
      "    records = fix_frame_records_filenames(inspect.getinnerframes(etb, context))\n",
      "  File \"/Users/hiradekeishi/opt/anaconda3/envs/py3-TF2.0/lib/python3.7/inspect.py\", line 1502, in getinnerframes\n",
      "    frameinfo = (tb.tb_frame,) + getframeinfo(tb, context)\n",
      "  File \"/Users/hiradekeishi/opt/anaconda3/envs/py3-TF2.0/lib/python3.7/inspect.py\", line 1460, in getframeinfo\n",
      "    filename = getsourcefile(frame) or getfile(frame)\n",
      "  File \"/Users/hiradekeishi/opt/anaconda3/envs/py3-TF2.0/lib/python3.7/inspect.py\", line 696, in getsourcefile\n",
      "    if getattr(getmodule(object, filename), '__loader__', None) is not None:\n",
      "  File \"/Users/hiradekeishi/opt/anaconda3/envs/py3-TF2.0/lib/python3.7/inspect.py\", line 733, in getmodule\n",
      "    if ismodule(module) and hasattr(module, '__file__'):\n",
      "  File \"/Users/hiradekeishi/opt/anaconda3/envs/py3-TF2.0/lib/python3.7/site-packages/tensorflow/__init__.py\", line 50, in __getattr__\n",
      "    from ._api.v2 import bitwise\n",
      "  File \"/Users/hiradekeishi/opt/anaconda3/envs/py3-TF2.0/lib/python3.7/site-packages/tensorflow/__init__.py\", line 44, in _load\n",
      "  File \"/Users/hiradekeishi/opt/anaconda3/envs/py3-TF2.0/lib/python3.7/importlib/__init__.py\", line 127, in import_module\n",
      "    return _bootstrap._gcd_import(name[level:], package, level)\n",
      "  File \"<frozen importlib._bootstrap>\", line 1006, in _gcd_import\n",
      "  File \"<frozen importlib._bootstrap>\", line 983, in _find_and_load\n",
      "  File \"<frozen importlib._bootstrap>\", line 965, in _find_and_load_unlocked\n",
      "ModuleNotFoundError: No module named 'tensorflow_core.estimator'\n",
      " database. History logging moved to new session 90\n",
      "Traceback (most recent call last):\n",
      "  File \"/Users/hiradekeishi/opt/anaconda3/envs/py3-TF2.0/lib/python3.7/site-packages/IPython/core/interactiveshell.py\", line 3457, in run_code\n",
      "    exec(code_obj, self.user_global_ns, self.user_ns)\n",
      "  File \"/var/folders/7_/5ly65s3j46zcgtgg9r0sjm940000gn/T/ipykernel_87487/1320733958.py\", line 1, in <module>\n",
      "    print('\\nTest loss: {0:.2f}. Test accuracy: {1:.2f}%'.format(test_loss, test_accuracy*100.))\n",
      "NameError: name 'test_loss' is not defined\n",
      "\n",
      "During handling of the above exception, another exception occurred:\n",
      "\n",
      "Traceback (most recent call last):\n",
      "  File \"/Users/hiradekeishi/opt/anaconda3/envs/py3-TF2.0/lib/python3.7/site-packages/IPython/core/interactiveshell.py\", line 2077, in showtraceback\n",
      "    stb = value._render_traceback_()\n",
      "AttributeError: 'NameError' object has no attribute '_render_traceback_'\n",
      "\n",
      "During handling of the above exception, another exception occurred:\n",
      "\n",
      "Traceback (most recent call last):\n",
      "  File \"/Users/hiradekeishi/opt/anaconda3/envs/py3-TF2.0/lib/python3.7/site-packages/IPython/core/interactiveshell.py\", line 3377, in run_ast_nodes\n",
      "    if (await self.run_code(code, result,  async_=asy)):\n",
      "  File \"/Users/hiradekeishi/opt/anaconda3/envs/py3-TF2.0/lib/python3.7/site-packages/IPython/core/interactiveshell.py\", line 3474, in run_code\n",
      "    self.showtraceback(running_compiled_code=True)\n",
      "  File \"/Users/hiradekeishi/opt/anaconda3/envs/py3-TF2.0/lib/python3.7/site-packages/IPython/core/interactiveshell.py\", line 2080, in showtraceback\n",
      "    value, tb, tb_offset=tb_offset)\n",
      "  File \"/Users/hiradekeishi/opt/anaconda3/envs/py3-TF2.0/lib/python3.7/site-packages/IPython/core/ultratb.py\", line 1368, in structured_traceback\n",
      "    self, etype, value, tb, tb_offset, number_of_lines_of_context)\n",
      "  File \"/Users/hiradekeishi/opt/anaconda3/envs/py3-TF2.0/lib/python3.7/site-packages/IPython/core/ultratb.py\", line 1268, in structured_traceback\n",
      "    self, etype, value, tb, tb_offset, number_of_lines_of_context\n",
      "  File \"/Users/hiradekeishi/opt/anaconda3/envs/py3-TF2.0/lib/python3.7/site-packages/IPython/core/ultratb.py\", line 1125, in structured_traceback\n",
      "    tb_offset)\n",
      "  File \"/Users/hiradekeishi/opt/anaconda3/envs/py3-TF2.0/lib/python3.7/site-packages/IPython/core/ultratb.py\", line 1082, in format_exception_as_a_whole\n",
      "    last_unique, recursion_repeat = find_recursion(orig_etype, evalue, records)\n",
      "  File \"/Users/hiradekeishi/opt/anaconda3/envs/py3-TF2.0/lib/python3.7/site-packages/IPython/core/ultratb.py\", line 382, in find_recursion\n",
      "    return len(records), 0\n",
      "TypeError: object of type 'NoneType' has no len()\n",
      "\n",
      "During handling of the above exception, another exception occurred:\n",
      "\n",
      "Traceback (most recent call last):\n",
      "  File \"/Users/hiradekeishi/opt/anaconda3/envs/py3-TF2.0/lib/python3.7/site-packages/IPython/core/interactiveshell.py\", line 2077, in showtraceback\n",
      "    stb = value._render_traceback_()\n",
      "AttributeError: 'TypeError' object has no attribute '_render_traceback_'\n",
      "\n",
      "During handling of the above exception, another exception occurred:\n",
      "\n",
      "Traceback (most recent call last):\n",
      "  File \"/Users/hiradekeishi/opt/anaconda3/envs/py3-TF2.0/lib/python3.7/site-packages/IPython/core/ultratb.py\", line 1101, in get_records\n",
      "    return _fixed_getinnerframes(etb, number_of_lines_of_context, tb_offset)\n",
      "  File \"/Users/hiradekeishi/opt/anaconda3/envs/py3-TF2.0/lib/python3.7/site-packages/IPython/core/ultratb.py\", line 248, in wrapped\n",
      "    return f(*args, **kwargs)\n",
      "  File \"/Users/hiradekeishi/opt/anaconda3/envs/py3-TF2.0/lib/python3.7/site-packages/IPython/core/ultratb.py\", line 281, in _fixed_getinnerframes\n",
      "    records = fix_frame_records_filenames(inspect.getinnerframes(etb, context))\n",
      "  File \"/Users/hiradekeishi/opt/anaconda3/envs/py3-TF2.0/lib/python3.7/inspect.py\", line 1502, in getinnerframes\n",
      "    frameinfo = (tb.tb_frame,) + getframeinfo(tb, context)\n",
      "  File \"/Users/hiradekeishi/opt/anaconda3/envs/py3-TF2.0/lib/python3.7/inspect.py\", line 1460, in getframeinfo\n",
      "    filename = getsourcefile(frame) or getfile(frame)\n",
      "  File \"/Users/hiradekeishi/opt/anaconda3/envs/py3-TF2.0/lib/python3.7/inspect.py\", line 696, in getsourcefile\n",
      "    if getattr(getmodule(object, filename), '__loader__', None) is not None:\n",
      "  File \"/Users/hiradekeishi/opt/anaconda3/envs/py3-TF2.0/lib/python3.7/inspect.py\", line 733, in getmodule\n",
      "    if ismodule(module) and hasattr(module, '__file__'):\n",
      "  File \"/Users/hiradekeishi/opt/anaconda3/envs/py3-TF2.0/lib/python3.7/site-packages/tensorflow/__init__.py\", line 50, in __getattr__\n",
      "    from ._api.v2 import bitwise\n",
      "  File \"/Users/hiradekeishi/opt/anaconda3/envs/py3-TF2.0/lib/python3.7/site-packages/tensorflow/__init__.py\", line 44, in _load\n",
      "  File \"/Users/hiradekeishi/opt/anaconda3/envs/py3-TF2.0/lib/python3.7/importlib/__init__.py\", line 127, in import_module\n",
      "    return _bootstrap._gcd_import(name[level:], package, level)\n",
      "  File \"<frozen importlib._bootstrap>\", line 1006, in _gcd_import\n",
      "  File \"<frozen importlib._bootstrap>\", line 983, in _find_and_load\n",
      "  File \"<frozen importlib._bootstrap>\", line 965, in _find_and_load_unlocked\n",
      "ModuleNotFoundError: No module named 'tensorflow_core.estimator'\n",
      "Traceback (most recent call last):\n",
      "  File \"/Users/hiradekeishi/opt/anaconda3/envs/py3-TF2.0/lib/python3.7/site-packages/IPython/core/interactiveshell.py\", line 3457, in run_code\n",
      "    exec(code_obj, self.user_global_ns, self.user_ns)\n",
      "  File \"/var/folders/7_/5ly65s3j46zcgtgg9r0sjm940000gn/T/ipykernel_87487/1320733958.py\", line 1, in <module>\n",
      "    print('\\nTest loss: {0:.2f}. Test accuracy: {1:.2f}%'.format(test_loss, test_accuracy*100.))\n",
      "NameError: name 'test_loss' is not defined\n",
      "\n",
      "During handling of the above exception, another exception occurred:\n",
      "\n",
      "Traceback (most recent call last):\n",
      "  File \"/Users/hiradekeishi/opt/anaconda3/envs/py3-TF2.0/lib/python3.7/site-packages/IPython/core/interactiveshell.py\", line 2077, in showtraceback\n",
      "    stb = value._render_traceback_()\n",
      "AttributeError: 'NameError' object has no attribute '_render_traceback_'\n",
      "\n",
      "During handling of the above exception, another exception occurred:\n",
      "\n",
      "Traceback (most recent call last):\n",
      "  File \"/Users/hiradekeishi/opt/anaconda3/envs/py3-TF2.0/lib/python3.7/site-packages/IPython/core/interactiveshell.py\", line 3377, in run_ast_nodes\n",
      "    if (await self.run_code(code, result,  async_=asy)):\n",
      "  File \"/Users/hiradekeishi/opt/anaconda3/envs/py3-TF2.0/lib/python3.7/site-packages/IPython/core/interactiveshell.py\", line 3474, in run_code\n",
      "    self.showtraceback(running_compiled_code=True)\n",
      "  File \"/Users/hiradekeishi/opt/anaconda3/envs/py3-TF2.0/lib/python3.7/site-packages/IPython/core/interactiveshell.py\", line 2080, in showtraceback\n",
      "    value, tb, tb_offset=tb_offset)\n",
      "  File \"/Users/hiradekeishi/opt/anaconda3/envs/py3-TF2.0/lib/python3.7/site-packages/IPython/core/ultratb.py\", line 1368, in structured_traceback\n",
      "    self, etype, value, tb, tb_offset, number_of_lines_of_context)\n",
      "  File \"/Users/hiradekeishi/opt/anaconda3/envs/py3-TF2.0/lib/python3.7/site-packages/IPython/core/ultratb.py\", line 1268, in structured_traceback\n",
      "    self, etype, value, tb, tb_offset, number_of_lines_of_context\n",
      "  File \"/Users/hiradekeishi/opt/anaconda3/envs/py3-TF2.0/lib/python3.7/site-packages/IPython/core/ultratb.py\", line 1125, in structured_traceback\n",
      "    tb_offset)\n",
      "  File \"/Users/hiradekeishi/opt/anaconda3/envs/py3-TF2.0/lib/python3.7/site-packages/IPython/core/ultratb.py\", line 1082, in format_exception_as_a_whole\n",
      "    last_unique, recursion_repeat = find_recursion(orig_etype, evalue, records)\n",
      "  File \"/Users/hiradekeishi/opt/anaconda3/envs/py3-TF2.0/lib/python3.7/site-packages/IPython/core/ultratb.py\", line 382, in find_recursion\n",
      "    return len(records), 0\n",
      "TypeError: object of type 'NoneType' has no len()\n",
      "\n",
      "During handling of the above exception, another exception occurred:\n",
      "\n",
      "Traceback (most recent call last):\n",
      "  File \"/Users/hiradekeishi/opt/anaconda3/envs/py3-TF2.0/lib/python3.7/site-packages/IPython/core/interactiveshell.py\", line 2077, in showtraceback\n",
      "    stb = value._render_traceback_()\n",
      "AttributeError: 'TypeError' object has no attribute '_render_traceback_'\n",
      "\n",
      "During handling of the above exception, another exception occurred:\n",
      "\n",
      "Traceback (most recent call last):\n",
      "  File \"/Users/hiradekeishi/opt/anaconda3/envs/py3-TF2.0/lib/python3.7/site-packages/IPython/core/interactiveshell.py\", line 2960, in _run_cell\n",
      "    return runner(coro)\n",
      "  File \"/Users/hiradekeishi/opt/anaconda3/envs/py3-TF2.0/lib/python3.7/site-packages/IPython/core/async_helpers.py\", line 78, in _pseudo_sync_runner\n",
      "    coro.send(None)\n",
      "  File \"/Users/hiradekeishi/opt/anaconda3/envs/py3-TF2.0/lib/python3.7/site-packages/IPython/core/interactiveshell.py\", line 3186, in run_cell_async\n",
      "    interactivity=interactivity, compiler=compiler, result=result)\n",
      "  File \"/Users/hiradekeishi/opt/anaconda3/envs/py3-TF2.0/lib/python3.7/site-packages/IPython/core/interactiveshell.py\", line 3396, in run_ast_nodes\n",
      "    self.showtraceback()\n",
      "  File \"/Users/hiradekeishi/opt/anaconda3/envs/py3-TF2.0/lib/python3.7/site-packages/IPython/core/interactiveshell.py\", line 2080, in showtraceback\n",
      "    value, tb, tb_offset=tb_offset)\n",
      "  File \"/Users/hiradekeishi/opt/anaconda3/envs/py3-TF2.0/lib/python3.7/site-packages/IPython/core/ultratb.py\", line 1368, in structured_traceback\n",
      "    self, etype, value, tb, tb_offset, number_of_lines_of_context)\n",
      "  File \"/Users/hiradekeishi/opt/anaconda3/envs/py3-TF2.0/lib/python3.7/site-packages/IPython/core/ultratb.py\", line 1268, in structured_traceback\n",
      "    self, etype, value, tb, tb_offset, number_of_lines_of_context\n",
      "  File \"/Users/hiradekeishi/opt/anaconda3/envs/py3-TF2.0/lib/python3.7/site-packages/IPython/core/ultratb.py\", line 1143, in structured_traceback\n",
      "    chained_exceptions_tb_offset)\n",
      "  File \"/Users/hiradekeishi/opt/anaconda3/envs/py3-TF2.0/lib/python3.7/site-packages/IPython/core/ultratb.py\", line 1082, in format_exception_as_a_whole\n",
      "    last_unique, recursion_repeat = find_recursion(orig_etype, evalue, records)\n",
      "  File \"/Users/hiradekeishi/opt/anaconda3/envs/py3-TF2.0/lib/python3.7/site-packages/IPython/core/ultratb.py\", line 382, in find_recursion\n",
      "    return len(records), 0\n",
      "TypeError: object of type 'NoneType' has no len()\n",
      "\n",
      "During handling of the above exception, another exception occurred:\n",
      "\n",
      "Traceback (most recent call last):\n",
      "  File \"/Users/hiradekeishi/opt/anaconda3/envs/py3-TF2.0/lib/python3.7/site-packages/IPython/core/interactiveshell.py\", line 2077, in showtraceback\n",
      "    stb = value._render_traceback_()\n",
      "AttributeError: 'TypeError' object has no attribute '_render_traceback_'\n",
      "\n",
      "During handling of the above exception, another exception occurred:\n",
      "\n",
      "Traceback (most recent call last):\n",
      "  File \"/Users/hiradekeishi/opt/anaconda3/envs/py3-TF2.0/lib/python3.7/site-packages/IPython/core/ultratb.py\", line 1101, in get_records\n",
      "    return _fixed_getinnerframes(etb, number_of_lines_of_context, tb_offset)\n",
      "  File \"/Users/hiradekeishi/opt/anaconda3/envs/py3-TF2.0/lib/python3.7/site-packages/IPython/core/ultratb.py\", line 248, in wrapped\n",
      "    return f(*args, **kwargs)\n",
      "  File \"/Users/hiradekeishi/opt/anaconda3/envs/py3-TF2.0/lib/python3.7/site-packages/IPython/core/ultratb.py\", line 281, in _fixed_getinnerframes\n",
      "    records = fix_frame_records_filenames(inspect.getinnerframes(etb, context))\n",
      "  File \"/Users/hiradekeishi/opt/anaconda3/envs/py3-TF2.0/lib/python3.7/inspect.py\", line 1502, in getinnerframes\n",
      "    frameinfo = (tb.tb_frame,) + getframeinfo(tb, context)\n",
      "  File \"/Users/hiradekeishi/opt/anaconda3/envs/py3-TF2.0/lib/python3.7/inspect.py\", line 1460, in getframeinfo\n",
      "    filename = getsourcefile(frame) or getfile(frame)\n",
      "  File \"/Users/hiradekeishi/opt/anaconda3/envs/py3-TF2.0/lib/python3.7/inspect.py\", line 696, in getsourcefile\n",
      "    if getattr(getmodule(object, filename), '__loader__', None) is not None:\n",
      "  File \"/Users/hiradekeishi/opt/anaconda3/envs/py3-TF2.0/lib/python3.7/inspect.py\", line 733, in getmodule\n",
      "    if ismodule(module) and hasattr(module, '__file__'):\n",
      "  File \"/Users/hiradekeishi/opt/anaconda3/envs/py3-TF2.0/lib/python3.7/site-packages/tensorflow/__init__.py\", line 50, in __getattr__\n",
      "    from ._api.v2 import bitwise\n",
      "  File \"/Users/hiradekeishi/opt/anaconda3/envs/py3-TF2.0/lib/python3.7/site-packages/tensorflow/__init__.py\", line 44, in _load\n",
      "  File \"/Users/hiradekeishi/opt/anaconda3/envs/py3-TF2.0/lib/python3.7/importlib/__init__.py\", line 127, in import_module\n",
      "    return _bootstrap._gcd_import(name[level:], package, level)\n",
      "  File \"<frozen importlib._bootstrap>\", line 1006, in _gcd_import\n",
      "  File \"<frozen importlib._bootstrap>\", line 983, in _find_and_load\n",
      "  File \"<frozen importlib._bootstrap>\", line 965, in _find_and_load_unlocked\n",
      "ModuleNotFoundError: No module named 'tensorflow_core.estimator'\n"
     ]
    }
   ],
   "source": [
    "print('\\nTest loss: {0:.2f}. Test accuracy: {1:.2f}%'.format(test_loss, test_accuracy*100.))"
   ]
  },
  {
   "cell_type": "code",
   "execution_count": null,
   "id": "9bbb4875",
   "metadata": {},
   "outputs": [],
   "source": []
  }
 ],
 "metadata": {
  "kernelspec": {
   "display_name": "Python 3 (ipykernel)",
   "language": "python",
   "name": "python3"
  },
  "language_info": {
   "codemirror_mode": {
    "name": "ipython",
    "version": 3
   },
   "file_extension": ".py",
   "mimetype": "text/x-python",
   "name": "python",
   "nbconvert_exporter": "python",
   "pygments_lexer": "ipython3",
   "version": "3.7.11"
  }
 },
 "nbformat": 4,
 "nbformat_minor": 5
}
